<?xml version="1.0" encoding="UTF-8"?>
<!-- Generated by org.testng.reporters.JUnitReportReporter -->
<testsuite hostname="SanthoshN" failures="6" tests="16" name="org.ee.test.TC_002_DashboardTest" time="169.176" errors="0" timestamp="16 Feb 2025 11:25:22 GMT" skipped="0">
  <testcase classname="org.ee.test.TC_002_DashboardTest" name="loginTestWithValidData" time="8.198">
    <failure message="expected [https://naveenautomationlabs.com/opencart/index.php?route=account/account] but found [https://naveenautomationlabs.com/opencart/index.php?route=account/login]" type="java.lang.AssertionError">
      <![CDATA[java.lang.AssertionError: expected [https://naveenautomationlabs.com/opencart/index.php?route=account/account] but found [https://naveenautomationlabs.com/opencart/index.php?route=account/login]
at org.testng.Assert.fail(Assert.java:96)
at org.testng.Assert.failNotEquals(Assert.java:776)
at org.testng.Assert.assertEqualsImpl(Assert.java:137)
at org.testng.Assert.assertEquals(Assert.java:118)
at org.testng.Assert.assertEquals(Assert.java:453)
at org.testng.Assert.assertEquals(Assert.java:463)
at org.ee.test.TC_002_DashboardTest.loginTestWithValidData(TC_002_DashboardTest.java:32)
at java.base/jdk.internal.reflect.DirectMethodHandleAccessor.invoke(DirectMethodHandleAccessor.java:103)
at java.base/java.lang.reflect.Method.invoke(Method.java:580)
at org.testng.internal.MethodInvocationHelper.invokeMethod(MethodInvocationHelper.java:124)
at org.testng.internal.Invoker.invokeMethod(Invoker.java:583)
at org.testng.internal.Invoker.invokeTestMethod(Invoker.java:719)
at org.testng.internal.Invoker.invokeTestMethods(Invoker.java:989)
at org.testng.internal.TestMethodWorker.invokeTestMethods(TestMethodWorker.java:125)
at org.testng.internal.TestMethodWorker.run(TestMethodWorker.java:109)
at org.testng.TestRunner.privateRun(TestRunner.java:648)
at org.testng.TestRunner.run(TestRunner.java:505)
at org.testng.SuiteRunner.runTest(SuiteRunner.java:455)
at org.testng.SuiteRunner.access$000(SuiteRunner.java:40)
at org.testng.SuiteRunner$SuiteWorker.run(SuiteRunner.java:489)
at org.testng.internal.thread.ThreadUtil$1.call(ThreadUtil.java:52)
at java.base/java.util.concurrent.FutureTask.run(FutureTask.java:317)
at java.base/java.util.concurrent.ThreadPoolExecutor.runWorker(ThreadPoolExecutor.java:1144)
at java.base/java.util.concurrent.ThreadPoolExecutor$Worker.run(ThreadPoolExecutor.java:642)
at java.base/java.lang.Thread.run(Thread.java:1583)
]]>
    </failure>
  </testcase> <!-- loginTestWithValidData -->
  <testcase classname="org.ee.test.TC_002_DashboardTest" name="loginTestWithValidData" time="12.346"/>
  <testcase classname="org.ee.test.TC_002_DashboardTest" name="loginTesWithInvalidData" time="8.969"/>
  <testcase classname="org.ee.test.TC_002_DashboardTest" name="loginTestWithValidData" time="10.550">
    <failure message="expected [https://naveenautomationlabs.com/opencart/index.php?route=account/account] but found [https://naveenautomationlabs.com/opencart/index.php?route=account/login]" type="java.lang.AssertionError">
      <![CDATA[java.lang.AssertionError: expected [https://naveenautomationlabs.com/opencart/index.php?route=account/account] but found [https://naveenautomationlabs.com/opencart/index.php?route=account/login]
at org.testng.Assert.fail(Assert.java:96)
at org.testng.Assert.failNotEquals(Assert.java:776)
at org.testng.Assert.assertEqualsImpl(Assert.java:137)
at org.testng.Assert.assertEquals(Assert.java:118)
at org.testng.Assert.assertEquals(Assert.java:453)
at org.testng.Assert.assertEquals(Assert.java:463)
at org.ee.test.TC_002_DashboardTest.loginTestWithValidData(TC_002_DashboardTest.java:32)
at java.base/jdk.internal.reflect.DirectMethodHandleAccessor.invoke(DirectMethodHandleAccessor.java:103)
at java.base/java.lang.reflect.Method.invoke(Method.java:580)
at org.testng.internal.MethodInvocationHelper.invokeMethod(MethodInvocationHelper.java:124)
at org.testng.internal.Invoker.invokeMethod(Invoker.java:583)
at org.testng.internal.Invoker.invokeTestMethod(Invoker.java:719)
at org.testng.internal.Invoker.invokeTestMethods(Invoker.java:989)
at org.testng.internal.TestMethodWorker.invokeTestMethods(TestMethodWorker.java:125)
at org.testng.internal.TestMethodWorker.run(TestMethodWorker.java:109)
at org.testng.TestRunner.privateRun(TestRunner.java:648)
at org.testng.TestRunner.run(TestRunner.java:505)
at org.testng.SuiteRunner.runTest(SuiteRunner.java:455)
at org.testng.SuiteRunner.access$000(SuiteRunner.java:40)
at org.testng.SuiteRunner$SuiteWorker.run(SuiteRunner.java:489)
at org.testng.internal.thread.ThreadUtil$1.call(ThreadUtil.java:52)
at java.base/java.util.concurrent.FutureTask.run(FutureTask.java:317)
at java.base/java.util.concurrent.ThreadPoolExecutor.runWorker(ThreadPoolExecutor.java:1144)
at java.base/java.util.concurrent.ThreadPoolExecutor$Worker.run(ThreadPoolExecutor.java:642)
at java.base/java.lang.Thread.run(Thread.java:1583)
]]>
    </failure>
  </testcase> <!-- loginTestWithValidData -->
  <testcase classname="org.ee.test.TC_002_DashboardTest" name="loginTestWithValidData" time="14.043">
    <failure message="expected [https://naveenautomationlabs.com/opencart/index.php?route=account/account] but found [https://naveenautomationlabs.com/opencart/index.php?route=account/login]" type="java.lang.AssertionError">
      <![CDATA[java.lang.AssertionError: expected [https://naveenautomationlabs.com/opencart/index.php?route=account/account] but found [https://naveenautomationlabs.com/opencart/index.php?route=account/login]
at org.testng.Assert.fail(Assert.java:96)
at org.testng.Assert.failNotEquals(Assert.java:776)
at org.testng.Assert.assertEqualsImpl(Assert.java:137)
at org.testng.Assert.assertEquals(Assert.java:118)
at org.testng.Assert.assertEquals(Assert.java:453)
at org.testng.Assert.assertEquals(Assert.java:463)
at org.ee.test.TC_002_DashboardTest.loginTestWithValidData(TC_002_DashboardTest.java:32)
at java.base/jdk.internal.reflect.DirectMethodHandleAccessor.invoke(DirectMethodHandleAccessor.java:103)
at java.base/java.lang.reflect.Method.invoke(Method.java:580)
at org.testng.internal.MethodInvocationHelper.invokeMethod(MethodInvocationHelper.java:124)
at org.testng.internal.Invoker.invokeMethod(Invoker.java:583)
at org.testng.internal.Invoker.invokeTestMethod(Invoker.java:719)
at org.testng.internal.Invoker.invokeTestMethods(Invoker.java:989)
at org.testng.internal.TestMethodWorker.invokeTestMethods(TestMethodWorker.java:125)
at org.testng.internal.TestMethodWorker.run(TestMethodWorker.java:109)
at org.testng.TestRunner.privateRun(TestRunner.java:648)
at org.testng.TestRunner.run(TestRunner.java:505)
at org.testng.SuiteRunner.runTest(SuiteRunner.java:455)
at org.testng.SuiteRunner.access$000(SuiteRunner.java:40)
at org.testng.SuiteRunner$SuiteWorker.run(SuiteRunner.java:489)
at org.testng.internal.thread.ThreadUtil$1.call(ThreadUtil.java:52)
at java.base/java.util.concurrent.FutureTask.run(FutureTask.java:317)
at java.base/java.util.concurrent.ThreadPoolExecutor.runWorker(ThreadPoolExecutor.java:1144)
at java.base/java.util.concurrent.ThreadPoolExecutor$Worker.run(ThreadPoolExecutor.java:642)
at java.base/java.lang.Thread.run(Thread.java:1583)
]]>
    </failure>
  </testcase> <!-- loginTestWithValidData -->
  <testcase classname="org.ee.test.TC_002_DashboardTest" name="loginTestWithValidData" time="8.223"/>
  <testcase classname="org.ee.test.TC_002_DashboardTest" name="loginTestWithValidData" time="12.209">
    <failure message="expected [https://naveenautomationlabs.com/opencart/index.php?route=account/account] but found [https://naveenautomationlabs.com/opencart/index.php?route=account/login]" type="java.lang.AssertionError">
      <![CDATA[java.lang.AssertionError: expected [https://naveenautomationlabs.com/opencart/index.php?route=account/account] but found [https://naveenautomationlabs.com/opencart/index.php?route=account/login]
at org.testng.Assert.fail(Assert.java:96)
at org.testng.Assert.failNotEquals(Assert.java:776)
at org.testng.Assert.assertEqualsImpl(Assert.java:137)
at org.testng.Assert.assertEquals(Assert.java:118)
at org.testng.Assert.assertEquals(Assert.java:453)
at org.testng.Assert.assertEquals(Assert.java:463)
at org.ee.test.TC_002_DashboardTest.loginTestWithValidData(TC_002_DashboardTest.java:32)
at java.base/jdk.internal.reflect.DirectMethodHandleAccessor.invoke(DirectMethodHandleAccessor.java:103)
at java.base/java.lang.reflect.Method.invoke(Method.java:580)
at org.testng.internal.MethodInvocationHelper.invokeMethod(MethodInvocationHelper.java:124)
at org.testng.internal.Invoker.invokeMethod(Invoker.java:583)
at org.testng.internal.Invoker.invokeTestMethod(Invoker.java:719)
at org.testng.internal.Invoker.invokeTestMethods(Invoker.java:989)
at org.testng.internal.TestMethodWorker.invokeTestMethods(TestMethodWorker.java:125)
at org.testng.internal.TestMethodWorker.run(TestMethodWorker.java:109)
at org.testng.TestRunner.privateRun(TestRunner.java:648)
at org.testng.TestRunner.run(TestRunner.java:505)
at org.testng.SuiteRunner.runTest(SuiteRunner.java:455)
at org.testng.SuiteRunner.access$000(SuiteRunner.java:40)
at org.testng.SuiteRunner$SuiteWorker.run(SuiteRunner.java:489)
at org.testng.internal.thread.ThreadUtil$1.call(ThreadUtil.java:52)
at java.base/java.util.concurrent.FutureTask.run(FutureTask.java:317)
at java.base/java.util.concurrent.ThreadPoolExecutor.runWorker(ThreadPoolExecutor.java:1144)
at java.base/java.util.concurrent.ThreadPoolExecutor$Worker.run(ThreadPoolExecutor.java:642)
at java.base/java.lang.Thread.run(Thread.java:1583)
]]>
    </failure>
  </testcase> <!-- loginTestWithValidData -->
  <testcase classname="org.ee.test.TC_002_DashboardTest" name="loginTestWithValidData" time="9.138">
    <failure message="expected [https://naveenautomationlabs.com/opencart/index.php?route=account/account] but found [https://naveenautomationlabs.com/opencart/index.php?route=account/login]" type="java.lang.AssertionError">
      <![CDATA[java.lang.AssertionError: expected [https://naveenautomationlabs.com/opencart/index.php?route=account/account] but found [https://naveenautomationlabs.com/opencart/index.php?route=account/login]
at org.testng.Assert.fail(Assert.java:96)
at org.testng.Assert.failNotEquals(Assert.java:776)
at org.testng.Assert.assertEqualsImpl(Assert.java:137)
at org.testng.Assert.assertEquals(Assert.java:118)
at org.testng.Assert.assertEquals(Assert.java:453)
at org.testng.Assert.assertEquals(Assert.java:463)
at org.ee.test.TC_002_DashboardTest.loginTestWithValidData(TC_002_DashboardTest.java:32)
at java.base/jdk.internal.reflect.DirectMethodHandleAccessor.invoke(DirectMethodHandleAccessor.java:103)
at java.base/java.lang.reflect.Method.invoke(Method.java:580)
at org.testng.internal.MethodInvocationHelper.invokeMethod(MethodInvocationHelper.java:124)
at org.testng.internal.Invoker.invokeMethod(Invoker.java:583)
at org.testng.internal.Invoker.invokeTestMethod(Invoker.java:719)
at org.testng.internal.Invoker.invokeTestMethods(Invoker.java:989)
at org.testng.internal.TestMethodWorker.invokeTestMethods(TestMethodWorker.java:125)
at org.testng.internal.TestMethodWorker.run(TestMethodWorker.java:109)
at org.testng.TestRunner.privateRun(TestRunner.java:648)
at org.testng.TestRunner.run(TestRunner.java:505)
at org.testng.SuiteRunner.runTest(SuiteRunner.java:455)
at org.testng.SuiteRunner.access$000(SuiteRunner.java:40)
at org.testng.SuiteRunner$SuiteWorker.run(SuiteRunner.java:489)
at org.testng.internal.thread.ThreadUtil$1.call(ThreadUtil.java:52)
at java.base/java.util.concurrent.FutureTask.run(FutureTask.java:317)
at java.base/java.util.concurrent.ThreadPoolExecutor.runWorker(ThreadPoolExecutor.java:1144)
at java.base/java.util.concurrent.ThreadPoolExecutor$Worker.run(ThreadPoolExecutor.java:642)
at java.base/java.lang.Thread.run(Thread.java:1583)
]]>
    </failure>
  </testcase> <!-- loginTestWithValidData -->
  <testcase classname="org.ee.test.TC_002_DashboardTest" name="loginTestWithValidData" time="8.416"/>
  <testcase classname="org.ee.test.TC_002_DashboardTest" name="loginTesWithInvalidData" time="8.020"/>
  <testcase classname="org.ee.test.TC_002_DashboardTest" name="loginTesWithInvalidData" time="11.630"/>
  <testcase classname="org.ee.test.TC_002_DashboardTest" name="loginTestWithValidData" time="12.218">
    <failure message="expected [https://naveenautomationlabs.com/opencart/index.php?route=account/account] but found [https://naveenautomationlabs.com/opencart/index.php?route=account/login]" type="java.lang.AssertionError">
      <![CDATA[java.lang.AssertionError: expected [https://naveenautomationlabs.com/opencart/index.php?route=account/account] but found [https://naveenautomationlabs.com/opencart/index.php?route=account/login]
at org.testng.Assert.fail(Assert.java:96)
at org.testng.Assert.failNotEquals(Assert.java:776)
at org.testng.Assert.assertEqualsImpl(Assert.java:137)
at org.testng.Assert.assertEquals(Assert.java:118)
at org.testng.Assert.assertEquals(Assert.java:453)
at org.testng.Assert.assertEquals(Assert.java:463)
at org.ee.test.TC_002_DashboardTest.loginTestWithValidData(TC_002_DashboardTest.java:32)
at java.base/jdk.internal.reflect.DirectMethodHandleAccessor.invoke(DirectMethodHandleAccessor.java:103)
at java.base/java.lang.reflect.Method.invoke(Method.java:580)
at org.testng.internal.MethodInvocationHelper.invokeMethod(MethodInvocationHelper.java:124)
at org.testng.internal.Invoker.invokeMethod(Invoker.java:583)
at org.testng.internal.Invoker.invokeTestMethod(Invoker.java:719)
at org.testng.internal.Invoker.invokeTestMethods(Invoker.java:989)
at org.testng.internal.TestMethodWorker.invokeTestMethods(TestMethodWorker.java:125)
at org.testng.internal.TestMethodWorker.run(TestMethodWorker.java:109)
at org.testng.TestRunner.privateRun(TestRunner.java:648)
at org.testng.TestRunner.run(TestRunner.java:505)
at org.testng.SuiteRunner.runTest(SuiteRunner.java:455)
at org.testng.SuiteRunner.access$000(SuiteRunner.java:40)
at org.testng.SuiteRunner$SuiteWorker.run(SuiteRunner.java:489)
at org.testng.internal.thread.ThreadUtil$1.call(ThreadUtil.java:52)
at java.base/java.util.concurrent.FutureTask.run(FutureTask.java:317)
at java.base/java.util.concurrent.ThreadPoolExecutor.runWorker(ThreadPoolExecutor.java:1144)
at java.base/java.util.concurrent.ThreadPoolExecutor$Worker.run(ThreadPoolExecutor.java:642)
at java.base/java.lang.Thread.run(Thread.java:1583)
]]>
    </failure>
  </testcase> <!-- loginTestWithValidData -->
  <testcase classname="org.ee.test.TC_002_DashboardTest" name="loginTesWithInvalidData" time="9.641"/>
  <testcase classname="org.ee.test.TC_002_DashboardTest" name="loginTesWithInvalidData" time="10.574"/>
  <testcase classname="org.ee.test.TC_002_DashboardTest" name="loginTesWithInvalidData" time="11.983"/>
  <testcase classname="org.ee.test.TC_002_DashboardTest" name="loginTestWithValidData" time="13.018"/>
</testsuite> <!-- org.ee.test.TC_002_DashboardTest -->
